Workbook

Sheet Sales_Data
A1: OrderID | B1: OrderDate | C1: Region | D1: Salesperson | E1: Product | F1: Category | G1: Units | H1: UnitPrice
A2: 1023 | B2: 2025-01-24 | C2: North | D2: RAVI KUMAR | E2: Office Chair | F2: Furniture | G2: 11 | H2: 6500
A3: 1134 | B3: 2025-03-29 | C3: North | D3: Ananya Rao | E3: Bookshelf | F3: Furniture | G3: 2 | H3: 4200
A4: 1115 | B4: 2025-03-18 | C4: West | D4: Rohan Shah | E4: Notebook Set | F4: Stationery | G4: 12 | H4: 350
A5: 1077 | B5: 2025-06-08 | C5: South | D5: Divya Sharma | E5: Office Chair | F5: Furniture | G5: 3 | H5: 6500
A6: 1009 | B6: 2025-06-04 | C6: East | D6: Sneha Das | E6: Bookshelf | F6: Furniture | G6: 9 | H6: 4200
A7: 1118 | B7: 2025-06-21 | C7: West | D7: Priya Mehta | E7: Bookshelf | F7: furniture | G7: 3 | H7: 4200
A8: 1149 | B8: 2025-01-31 | C8: South | D8: Karthik Iyer | E8: Wireless Mouse | F8: Electronics | G8: 12 | H8: 799
A9: 1158 | B9: 2025-05-28 | C9: North | D9: Ravi Kumar | E9: Office Chair | F9: Furniture | G9: 10 | H9: 6500
A10: 1111 | B10: 2025-04-09 | C10: South | D10: DIVYA SHARMA | E10: Wireless Mouse | F10: Electronics | G10: 7 | H10: 799
A11: 1151 | B11: 2025-05-04 | C11: East | D11: Amit Ghosh | E11: Wireless Mouse | F11: Electronics | G11: 4 | H11: 799
A12: 1091 | B12: 2025-03-18 | C12: East | D12: Amit Ghosh | E12: Gel Pen Pack | F12: Stationery | G12: 7 | H12: 120
A13: 1033 | B13: 2025-05-17 | C13: South | D13: Divya Sharma | E13: Bookshelf | F13: Furniture | G13: 9 | H13: 4200
... A25: 1165 | B25: 2025-04-26 | C25: West | D25: Rohan Shah | E25: Laptop Pro 14 | F25: Electronics | G25: 4 | H25: 68000
A26: 1047 | B26: 2025-03-13 | C26: West | D26: Priya Mehta | E26: Wireless Mouse | F26: Electronics | H26: 799
A27: 1012 | B27: 2025-06-19 | C27: South | D27: KARTHIK IYER | E27: Wireless Mouse | F27: Electronics | G27: 4 | H27: 799
A28: 1067 | B28: 2025-01-28 | C28: South | D28: KARTHIK IYER | E28: A4 Paper Ream | F28: Stationery | G28: 10 | H28: 250
A29: 1094 | B29: 2025-03-19 | C29: West | D29: Priya Mehta | E29: A4 Paper Ream | F29: Stationery | G29: 5 | H29: 250
A30: 1066 | B30: 2025-06-19 | C30: North | D30: Ravi Kumar | E30: A4 Paper Ream | F30: stationery | G30: 2 | H30: 250
A31: 1079 | B31: 2025-06-21 | C31: South | D31: Karthik Iyer | E31: Office Chair | F31: furniture | G31: 12 | H31: 6500
A32: 1048 | B32: 2025-05-21 | C32: North | D32: Ravi Kumar | E32: Notebook Set | F32: Stationery | G32: 1 | H32: 350
A33: 1126 | B33: 2025-02-21 | C33: North | D33: Ravi Kumar | E33: Standing Desk | F33: Furniture | G33: 3 | H33: 15500
A34: 1073 | B34: 2025-02-08 | C34: North | D34: Ananya Rao | E34: Bluetooth Speaker | F34: Electronics | G34: 9 | H34: 2999
A35: 1011 | B35: 2025-06-10 | C35: East | D35: Sneha Das | E35: Wireless Mouse | F35: Electronics | G35: 1 | H35: 799
A36: 1029 | B36: 2025-05-10 | C36: South | D36: Divya Sharma | E36: Gel Pen Pack | F36: Stationery | G36: 3 | H36: 120
A37: 1116 | B37: 2025-05-20 | C37: South | D37: Karthik Iyer | E37: Standing Desk | F37: Furniture | H37: 15500
A38: 1007 | B38: 2025-03-13 | C38: South | D38: Divya Sharma | E38: Gel Pen Pack | F38: Stationery | G38: 2 | H38: 120
A39: 1028 | B39: 2025-03-09 | C39: South | D39: Divya Sharma | E39: A4 Paper Ream | F39: Stationery | G39: 11 | H39: 250
A40: 1072 | B40: 2025-04-20 | C40: North | D40: Ravi Kumar | E40: Wireless Mouse | F40: Electronics | G40: 12 | H40: 799
A41: 1015 | B41: 2025-06-21 | C41: East | D41: Sneha Das | E41: Bluetooth Speaker | F41: Electronics | G41: 11 | H41: 2999
A42: 1100 | B42: 2025-01-19 | C42: West | D42: ROHAN SHAH | E42: Bluetooth Speaker | F42: Electronics | G42: 4 | H42: 2999
A43: 1051 | B43: 2025-04-08 | C43: North | D43: Ananya Rao | E43: A4 Paper Ream | F43: Stationery | G43: 8 | H43: 250
A44: 1016 | B44: 2025-02-13 | C44: South | D44: Divya Sharma | E44: Bookshelf | F44: Furniture | G44: 7 | H44: 4200
A45: 1081 | B45: 2025-02-21 | C45: West | D45: Rohan Shah | E45: A4 Paper Ream | F45: Stationery | G45: 4 | H45: 250
A46: 1109 | B46: 2025-01-20 | C46: East | D46: Sneha Das | E46: A4 Paper Ream | F46: Stationery | G46: 6 | H46: 250
A47: 1003 | B47: 2025-06-01 | C47: West | D47: Priya Mehta | E47: Laptop Pro 14 | F47: Electronics | G47: 2 | H47: 68000
A48: 1137 | B48: 2025-06-01 | C48: East | D48: Amit Ghosh | E48: Standing Desk | F48: Furniture | G48: 2 | H48: 15500
A49: 1157 | B49: 2025-01-30 | C49: North | D49: Ananya Rao | E49: Bookshelf | F49: furniture | G49: 2 | H49: 4200
... A111: 1085 | B111: 2025-03-08 | C111: South | D111: Karthik Iyer | E111: Laptop Pro 14 | F111: Electronics | G111: 2 | H111: 68000
A112: 1162 | B112: 2025-01-16 | C112: North | D112: Ravi Kumar | E112: Standing Desk | F112: Furniture | H112: 15500
...

Sheet Dashboard
B1: Sales Dashboard | L1: Search Manager | M1: Nikhil Verma
B2: Jan–Jun 2025 | Source: Cleaned_Data
L3: Order ID | M3: Region | N3: Sales Person | O3: Product | P3: Category | Q3: Units | R3: Unit Price | S3: Sales
L4: {=_xlfn._xlws.FILTER(_xlfn.HSTACK(Table2[OrderID],Table2[[Region Clean]:[Sales]]),Table2[Manager]=M1)} -> 1055 | M4: West | N4: Priya Mehta | O4: Laptop Pro 14 | P4: Electronics | Q4: 9 | R4: 68000 | S4: 612000
B5: Total Sales | D5: Total Orders | F5: Average Orders | H5: Top Region | J5: Top Sales Person | L5: 1114 | M5: West | N5: Rohan Shah | O5: Laptop Pro 14 | P5: Electronics | Q5: 6 | R5: 68000 | S5: 408000
B6: =SUM(Table2[Sales]) -> 9053158 | D6: =COUNTA(Table2[OrderID]) -> 180 | F6: =B6/D6 -> 50295.322 | H6: =INDEX('Pivot Tables'!D14:D17, MATCH(MAX('Pivot Tables'!E14:E17), 'Pivot Tables'!E14:E17, 0)) -> West | J6: =INDEX('Pivot Tables'!H4:H11,MATCH(MAX('Pivot Tables'!I4:I11),'Pivot Tables'!I4:I11,0)) -> Ravi Kumar | L6: 1074 | M6: West | N6: Priya Mehta | O6: Laptop Pro 14 | P6: Electronics | Q6: 5 | R6: 68000 | S6: 340000
L7: 1165 | M7: West | N7: Rohan Shah | O7: Laptop Pro 14 | P7: Electronics | Q7: 4 | R7: 68000 | S7: 272000
L8: 1107 | M8: West | N8: Rohan Shah | O8: Standing Desk | P8: Furniture | Q8: 11 | R8: 15500 | S8: 170500
L9: 1003 | M9: West | N9: Priya Mehta | O9: Laptop Pro 14 | P9: Electronics | Q9: 2 | R9: 68000 | S9: 136000
L10: 1084 | M10: West | N10: Rohan Shah | O10: Laptop Pro 14 | P10: Electronics | Q10: 2 | R10: 68000 | S10: 136000
L11: 1117 | M11: West | N11: Priya Mehta | O11: 27In Monitor | P11: Electronics | Q11: 6 | R11: 18500 | S11: 111000
L12: 1106 | M12: West | N12: Rohan Shah | O12: Office Chair | P12: Furniture | Q12: 12 | R12: 6500 | S12: 78000
L13: 1101 | M13: West | N13: Rohan Shah | O13: 27In Monitor | P13: Electronics | Q13: 4 | R13: 18500 | S13: 74000
L14: 1176 | M14: West | N14: Rohan Shah | O14: Office Chair | P14: Furniture | Q14: 10 | R14: 6500 | S14: 65000
L15: 1046 | M15: West | N15: Priya Mehta | O15: 27In Monitor | P15: Electronics | Q15: 3 | R15: 18500 | S15: 55500
L16: 1143 | M16: West | N16: Priya Mehta | O16: Bookshelf | P16: Furniture | Q16: 11 | R16: 4200 | S16: 46200
L17: 1013 | M17: West | N17: Rohan Shah | O17: Bookshelf | P17: Furniture | Q17: 11 | R17: 4200 | S17: 46200
L18: 1104 | M18: West | N18: Priya Mehta | O18: Bookshelf | P18: Furniture | Q18: 11 | R18: 4200 | S18: 46200
... L51: 1139 | M51: West | N51: Rohan Shah | O51: Laptop Pro 14 | P51: Electronics | Q51: 0 | R51: 68000 | S51: 0

Sheet Cleaned Dataset
A1: OrderID | B1: OrderDate | C1: Region Clean | D1: Sales Person | E1: Product | F1: Category | G1: Units | H1: Unit Price | I1: Sales | J1: Manager
A2: 1088 | B2: 45723 | C2: =PROPER(TRIM(Sales_Data!C52)) -> North | D2: =PROPER(TRIM(Sales_Data!D52)) -> Ananya Rao | E2: =PROPER(TRIM(Sales_Data!E52)) -> Laptop Pro 14 | F2: =PROPER(TRIM(Sales_Data!F52)) -> Electronics | G2: =IF(Sales_Data!G52=" ",0,Sales_Data!G52) -> 9 | H2: =Sales_Data!H52 -> 68000 | I2: =Table2[[#This Row],[Units]]*Table2[[#This Row],[Unit Price]] -> 612000 | J2: =_xlfn.XLOOKUP(Table2[[#This Row],[Region Clean]],Table4[Region],Table4[Manager]) -> Meera Nair
A3: 1055 | B3: 45807 | C3: =PROPER(TRIM(Sales_Data!C59)) -> West | D3: =PROPER(TRIM(Sales_Data!D59)) -> Priya Mehta | E3: =PROPER(TRIM(Sales_Data!E59)) -> Laptop Pro 14 | F3: =PROPER(TRIM(Sales_Data!F59)) -> Electronics | G3: =IF(Sales_Data!G59=" ",0,Sales_Data!G59) -> 9 | H3: =Sales_Data!H59 -> 68000 | I3: =Table2[[#This Row],[Units]]*Table2[[#This Row],[Unit Price]] -> 612000 | J3: =_xlfn.XLOOKUP(Table2[[#This Row],[Region Clean]],Table4[Region],Table4[Manager]) -> Nikhil Verma
A4: 1164 | B4: 45799 | C4: =PROPER(TRIM(Sales_Data!C91)) -> North | D4: =PROPER(TRIM(Sales_Data!D91)) -> Ravi Kumar | E4: =PROPER(TRIM(Sales_Data!E91)) -> Laptop Pro 14 | F4: =PROPER(TRIM(Sales_Data!F91)) -> Electronics | G4: =IF(Sales_Data!G91=" ",0,Sales_Data!G91) -> 7 | H4: =Sales_Data!H91 -> 68000 | I4: =Table2[[#This Row],[Units]]*Table2[[#This Row],[Unit Price]] -> 476000 | J4: =_xlfn.XLOOKUP(Table2[[#This Row],[Region Clean]],Table4[Region],Table4[Manager]) -> Meera Nair
A5: 1114 | B5: 45663 | C5: =PROPER(TRIM(Sales_Data!C167)) -> West | D5: =PROPER(TRIM(Sales_Data!D167)) -> Rohan Shah | E5: =PROPER(TRIM(Sales_Data!E167)) -> Laptop Pro 14 | F5: =PROPER(TRIM(Sales_Data!F167)) -> Electronics | G5: =IF(Sales_Data!G167=" ",0,Sales_Data!G167) -> 6 | H5: =Sales_Data!H167 -> 68000 | I5: =Table2[[#This Row],[Units]]*Table2[[#This Row],[Unit Price]] -> 408000 | J5: =_xlfn.XLOOKUP(Table2[[#This Row],[Region Clean]],Table4[Region],Table4[Manager]) -> Nikhil Verma
A6: 1074 | B6: 45695 | C6: =PROPER(TRIM(Sales_Data!C161)) -> West | D6: =PROPER(TRIM(Sales_Data!D161)) -> Priya Mehta | E6: =PROPER(TRIM(Sales_Data!E161)) -> Laptop Pro 14 | F6: =PROPER(TRIM(Sales_Data!F161)) -> Electronics | G6: =IF(Sales_Data!G161=" ",0,Sales_Data!G161) -> 5 | H6: =Sales_Data!H161 -> 68000 | I6: =Table2[[#This Row],[Units]]*Table2[[#This Row],[Unit Price]] -> 340000 | J6: =_xlfn.XLOOKUP(Table2[[#This Row],[Region Clean]],Table4[Region],Table4[Manager]) -> Nikhil Verma
A7: 1125 | B7: 45824 | C7: =PROPER(TRIM(Sales_Data!C159)) -> North | D7: =PROPER(TRIM(Sales_Data!D159)) -> Ravi Kumar | E7: =PROPER(TRIM(Sales_Data!E159)) -> Laptop Pro 14 | F7: =PROPER(TRIM(Sales_Data!F159)) -> Electronics | G7: =IF(Sales_Data!G159=" ",0,Sales_Data!G159) -> 4 | H7: =Sales_Data!H159 -> 68000 | I7: =Table2[[#This Row],[Units]]*Table2[[#This Row],[Unit Price]] -> 272000 | J7: =_xlfn.XLOOKUP(Table2[[#This Row],[Region Clean]],Table4[Region],Table4[Manager]) -> Meera Nair
A8: 1017 | B8: 45727 | C8: =PROPER(TRIM(Sales_Data!C81)) -> South | D8: =PROPER(TRIM(Sales_Data!D81)) -> Karthik Iyer | E8: =PROPER(TRIM(Sales_Data!E81)) -> Laptop Pro 14 | F8: =PROPER(TRIM(Sales_Data!F81)) -> Electronics | G8: =IF(Sales_Data!G81=" ",0,Sales_Data!G81) -> 4 | H8: =Sales_Data!H81 -> 68000 | I8: =Table2[[#This Row],[Units]]*Table2[[#This Row],[Unit Price]] -> 272000 | J8: =_xlfn.XLOOKUP(Table2[[#This Row],[Region Clean]],Table4[Region],Table4[Manager]) -> Arjun Reddy
A9: 1165 | B9: 45773 | C9: =PROPER(TRIM(Sales_Data!C25)) -> West | D9: =PROPER(TRIM(Sales_Data!D25)) -> Rohan Shah | E9: =PROPER(TRIM(Sales_Data!E25)) -> Laptop Pro 14 | F9: =PROPER(TRIM(Sales_Data!F25)) -> Electronics | G9: =IF(Sales_Data!G25=" ",0,Sales_Data!G25) -> 4 | H9: =Sales_Data!H25 -> 68000 | I9: =Table2[[#This Row],[Units]]*Table2[[#This Row],[Unit Price]] -> 272000 | J9: =_xlfn.XLOOKUP(Table2[[#This Row],[Region Clean]],Table4[Region],Table4[Manager]) -> Nikhil Verma
A10: 1130 | B10: 45664 | C10: =PROPER(TRIM(Sales_Data!C120)) -> East | D10: =PROPER(TRIM(Sales_Data!D120)) -> Amit Ghosh | E10: =PROPER(TRIM(Sales_Data!E120)) -> 27In Monitor | F10: =PROPER(TRIM(Sales_Data!F120)) -> Electronics | G10: =IF(Sales_Data!G120=" ",0,Sales_Data!G120) -> 12 | H10: =Sales_Data!H120 -> 18500 | I10: =Table2[[#This Row],[Units]]*Table2[[#This Row],[Unit Price]] -> 222000 | J10: =_xlfn.XLOOKUP(Table2[[#This Row],[Region Clean]],Table4[Region],Table4[Manager]) -> Kavita Bose
A11: 1050 | B11: 45781 | C11: =PROPER(TRIM(Sales_Data!C93)) -> South | D11: =PROPER(TRIM(Sales_Data!D93)) -> Karthik Iyer | E11: =PROPER(TRIM(Sales_Data!E93)) -> Laptop Pro 14 | F11: =PROPER(TRIM(Sales_Data!F93)) -> Electronics | G11: =IF(Sales_Data!G93=" ",0,Sales_Data!G93) -> 3 | H11: =Sales_Data!H93 -> 68000 | I11: =Table2[[#This Row],[Units]]*Table2[[#This Row],[Unit Price]] -> 204000 | J11: =_xlfn.XLOOKUP(Table2[[#This Row],[Region Clean]],Table4[Region],Table4[Manager]) -> Arjun Reddy
A12: 1058 | B12: 45721 | C12: =PROPER(TRIM(Sales_Data!C148)) -> North | D12: =PROPER(TRIM(Sales_Data!D148)) -> Ravi Kumar | E12: =PROPER(TRIM(Sales_Data!E148)) -> 27In Monitor | F12: =PROPER(TRIM(Sales_Data!F148)) -> Electronics | G12: =IF(Sales_Data!G148=" ",0,Sales_Data!G148) -> 11 | H12: =Sales_Data!H148 -> 18500 | I12: =Table2[[#This Row],[Units]]*Table2[[#This Row],[Unit Price]] -> 203500 | J12: =_xlfn.XLOOKUP(Table2[[#This Row],[Region Clean]],Table4[Region],Table4[Manager]) -> Meera Nair
A13: 1035 | B13: 45834 | C13: =PROPER(TRIM(Sales_Data!C131)) -> South | D13: =PROPER(TRIM(Sales_Data!D131)) -> Karthik Iyer | E13: =PROPER(TRIM(Sales_Data!E131)) -> 27In Monitor | F13: =PROPER(TRIM(Sales_Data!F131)) -> Electronics | G13: =IF(Sales_Data!G131=" ",0,Sales_Data!G131) -> 11 | H13: =Sales_Data!H131 -> 18500 | I13: =Table2[[#This Row],[Units]]*Table2[[#This Row],[Unit Price]] -> 203500 | J13: =_xlfn.XLOOKUP(Table2[[#This Row],[Region Clean]],Table4[Region],Table4[Manager]) -> Arjun Reddy
A14: 1150 | B14: 45795 | C14: =PROPER(TRIM(Sales_Data!C103)) -> South | D14: =PROPER(TRIM(Sales_Data!D103)) -> Divya Sharma | E14: =PROPER(TRIM(Sales_Data!E103)) -> Standing Desk | F14: =PROPER(TRIM(Sales_Data!F103)) -> Furniture | G14: =IF(Sales_Data!G103=" ",0,Sales_Data!G103) -> 12 | H14: =Sales_Data!H103 -> 15500 | I14: =Table2[[#This Row],[Units]]*Table2[[#This Row],[Unit Price]] -> 186000 | J14: =_xlfn.XLOOKUP(Table2[[#This Row],[Region Clean]],Table4[Region],Table4[Manager]) -> Arjun Reddy
A15: 1059 | B15: 45807 | C15: =PROPER(TRIM(Sales_Data!C99)) -> East | D15: =PROPER(TRIM(Sales_Data!D99)) -> Amit Ghosh | E15: =PROPER(TRIM(Sales_Data!E99)) -> Standing Desk | F15: =PROPER(TRIM(Sales_Data!F99)) -> Furniture | G15: =IF(Sales_Data!G99=" ",0,Sales_Data!G99) -> 11 | H15: =Sales_Data!H99 -> 15500 | I15: =Table2[[#This Row],[Units]]*Table2[[#This Row],[Unit Price]] -> 170500 | J15: =_xlfn.XLOOKUP(Table2[[#This Row],[Region Clean]],Table4[Region],Table4[Manager]) -> Kavita Bose
A16: 1075 | B16: 45751 | C16: =PROPER(TRIM(Sales_Data!C142)) -> North | D16: =PROPER(TRIM(Sales_Data!D142)) -> Ananya Rao | E16: =PROPER(TRIM(Sales_Data!E142)) -> Standing Desk | F16: =PROPER(TRIM(Sales_Data!F142)) -> Furniture | G16: =IF(Sales_Data!G142=" ",0,Sales_Data!G142) -> 11 | H16: =Sales_Data!H142 -> 15500 | I16: =Table2[[#This Row],[Units]]*Table2[[#This Row],[Unit Price]] -> 170500 | J16: =_xlfn.XLOOKUP(Table2[[#This Row],[Region Clean]],Table4[Region],Table4[Manager]) -> Meera Nair
A17: 1107 | B17: 45779 | C17: =PROPER(TRIM(Sales_Data!C139)) -> West | D17: =PROPER(TRIM(Sales_Data!D139)) -> Rohan Shah | E17: =PROPER(TRIM(Sales_Data!E139)) -> Standing Desk | F17: =PROPER(TRIM(Sales_Data!F139)) -> Furniture | G17: =IF(Sales_Data!G139=" ",0,Sales_Data!G139) -> 11 | H17: =Sales_Data!H139 -> 15500 | I17: =Table2[[#This Row],[Units]]*Table2[[#This Row],[Unit Price]] -> 170500 | J17: =_xlfn.XLOOKUP(Table2[[#This Row],[Region Clean]],Table4[Region],Table4[Manager]) -> Nikhil Verma
A18: 1049 | B18: 45681 | C18: =PROPER(TRIM(Sales_Data!C173)) -> South | D18: =PROPER(TRIM(Sales_Data!D173)) -> Divya Sharma | E18: =PROPER(TRIM(Sales_Data!E173)) -> 27In Monitor | F18: =PROPER(TRIM(Sales_Data!F173)) -> Electronics | G18: =IF(Sales_Data!G173=" ",0,Sales_Data!G173) -> 8 | H18: =Sales_Data!H173 -> 18500 | I18: =Table2[[#This Row],[Units]]*Table2[[#This Row],[Unit Price]] -> 148000 | J18: =_xlfn.XLOOKUP(Table2[[#This Row],[Region Clean]],Table4[Region],Table4[Manager]) -> Arjun Reddy
A19: 1034 | B19: 45700 | C19: =PROPER(TRIM(Sales_Data!C162)) -> East | D19: =PROPER(TRIM(Sales_Data!D162)) -> Amit Ghosh | E19: =PROPER(TRIM(Sales_Data!E162)) -> Standing Desk | F19: =PROPER(TRIM(Sales_Data!F162)) -> Furniture | G19: =IF(Sales_Data!G162=" ",0,Sales_Data!G162) -> 9 | H19: =Sales_Data!H162 -> 15500 | I19: =Table2[[#This Row],[Units]]*Table2[[#This Row],[Unit Price]] -> 139500 | J19: =_xlfn.XLOOKUP(Table2[[#This Row],[Region Clean]],Table4[Region],Table4[Manager]) -> Kavita Bose
A20: 1085 | B20: 45724 | C20: =PROPER(TRIM(Sales_Data!C111)) -> South | D20: =PROPER(TRIM(Sales_Data!D111)) -> Karthik Iyer | E20: =PROPER(TRIM(Sales_Data!E111)) -> Laptop Pro 14 | F20: =PROPER(TRIM(Sales_Data!F111)) -> Electronics | G20: =IF(Sales_Data!G111=" ",0,Sales_Data!G111) -> 2 | H20: =Sales_Data!H111 -> 68000 | I20: =Table2[[#This Row],[Units]]*Table2[[#This Row],[Unit Price]] -> 136000 | J20: =_xlfn.XLOOKUP(Table2[[#This Row],[Region Clean]],Table4[Region],Table4[Manager]) -> Arjun Reddy
A21: 1038 | B21: 45663 | C21: =PROPER(TRIM(Sales_Data!C134)) -> South | D21: =PROPER(TRIM(Sales_Data!D134)) -> Divya Sharma | E21: =PROPER(TRIM(Sales_Data!E134)) -> Laptop Pro 14 | F21: =PROPER(TRIM(Sales_Data!F134)) -> Electronics | G21: =IF(Sales_Data!G134=" ",0,Sales_Data!G134) -> 2 | H21: =Sales_Data!H134 -> 68000 | I21: =Table2[[#This Row],[Units]]*Table2[[#This Row],[Unit Price]] -> 136000 | J21: =_xlfn.XLOOKUP(Table2[[#This Row],[Region Clean]],Table4[Region],Table4[Manager]) -> Arjun Reddy
A22: 1003 | B22: 45809 | C22: =PROPER(TRIM(Sales_Data!C47)) -> West | D22: =PROPER(TRIM(Sales_Data!D47)) -> Priya Mehta | E22: =PROPER(TRIM(Sales_Data!E47)) -> Laptop Pro 14 | F22: =PROPER(TRIM(Sales_Data!F47)) -> Electronics | G22: =IF(Sales_Data!G47=" ",0,Sales_Data!G47) -> 2 | H22: =Sales_Data!H47 -> 68000 | I22: =Table2[[#This Row],[Units]]*Table2[[#This Row],[Unit Price]] -> 136000 | J22: =_xlfn.XLOOKUP(Table2[[#This Row],[Region Clean]],Table4[Region],Table4[Manager]) -> Nikhil Verma
A23: 1084 | B23: 45788 | C23: =PROPER(TRIM(Sales_Data!C85)) -> West | D23: =PROPER(TRIM(Sales_Data!D85)) -> Rohan Shah | E23: =PROPER(TRIM(Sales_Data!E85)) -> Laptop Pro 14 | F23: =PROPER(TRIM(Sales_Data!F85)) -> Electronics | G23: =IF(Sales_Data!G85=" ",0,Sales_Data!G85) -> 2 | H23: =Sales_Data!H85 -> 68000 | I23: =Table2[[#This Row],[Units]]*Table2[[#This Row],[Unit Price]] -> 136000 | J23: =_xlfn.XLOOKUP(Table2[[#This Row],[Region Clean]],Table4[Region],Table4[Manager]) -> Nikhil Verma
A24: 1082 | B24: 45715 | C24: =PROPER(TRIM(Sales_Data!C56)) -> North | D24: =PROPER(TRIM(Sales_Data!D56)) -> Ravi Kumar | E24: =PROPER(TRIM(Sales_Data!E56)) -> 27In Monitor | F24: =PROPER(TRIM(Sales_Data!F56)) -> Electronics | G24: =IF(Sales_Data!G56=" ",0,Sales_Data!G56) -> 6 | H24: =Sales_Data!H56 -> 18500 | I24: =Table2[[#This Row],[Units]]*Table2[[#This Row],[Unit Price]] -> 111000 | J24: =_xlfn.XLOOKUP(Table2[[#This Row],[Region Clean]],Table4[Region],Table4[Manager]) -> Meera Nair
A25: 1006 | B25: 45729 | C25: =PROPER(TRIM(Sales_Data!C90)) -> North | D25: =PROPER(TRIM(Sales_Data!D90)) -> Ravi Kumar | E25: =PROPER(TRIM(Sales_Data!E90)) -> 27In Monitor | F25: =PROPER(TRIM(Sales_Data!F90)) -> Electronics | G25: =IF(Sales_Data!G90=" ",0,Sales_Data!G90) -> 6 | H25: =Sales_Data!H90 -> 18500 | I25: =Table2[[#This Row],[Units]]*Table2[[#This Row],[Unit Price]] -> 111000 | J25: =_xlfn.XLOOKUP(Table2[[#This Row],[Region Clean]],Table4[Region],Table4[Manager]) -> Meera Nair
A26: 1117 | B26: 45769 | C26: =PROPER(TRIM(Sales_Data!C135)) -> West | D26: =PROPER(TRIM(Sales_Data!D135)) -> Priya Mehta | E26: =PROPER(TRIM(Sales_Data!E135)) -> 27In Monitor | F26: =PROPER(TRIM(Sales_Data!F135)) -> Electronics | G26: =IF(Sales_Data!G135=" ",0,Sales_Data!G135) -> 6 | H26: =Sales_Data!H135 -> 18500 | I26: =Table2[[#This Row],[Units]]*Table2[[#This Row],[Unit Price]] -> 111000 | J26: =_xlfn.XLOOKUP(Table2[[#This Row],[Region Clean]],Table4[Region],Table4[Manager]) -> Nikhil Verma
A27: 1092 | B27: 45836 | C27: =PROPER(TRIM(Sales_Data!C86)) -> East | D27: =PROPER(TRIM(Sales_Data!D86)) -> Sneha Das | E27: =PROPER(TRIM(Sales_Data!E86)) -> Standing Desk | F27: =PROPER(TRIM(Sales_Data!F86)) -> Furniture | G27: =IF(Sales_Data!G86=" ",0,Sales_Data!G86) -> 7 | H27: =Sales_Data!H86 -> 15500 | I27: =Table2[[#This Row],[Units]]*Table2[[#This Row],[Unit Price]] -> 108500 | J27: =_xlfn.XLOOKUP(Table2[[#This Row],[Region Clean]],Table4[Region],Table4[Manager]) -> Kavita Bose
A28: 1140 | B28: 45741 | C28: =PROPER(TRIM(Sales_Data!C100)) -> South | D28: =PROPER(TRIM(Sales_Data!D100)) -> Karthik Iyer | E28: =PROPER(TRIM(Sales_Data!E100)) -> Standing Desk | F28: =PROPER(TRIM(Sales_Data!F100)) -> Furniture | G28: =IF(Sales_Data!G100=" ",0,Sales_Data!G100) -> 6 | H28: =Sales_Data!H100 -> 15500 | I28: =Table2[[#This Row],[Units]]*Table2[[#This Row],[Unit Price]] -> 93000 | J28: =_xlfn.XLOOKUP(Table2[[#This Row],[Region Clean]],Table4[Region],Table4[Manager]) -> Arjun Reddy
A29: 1079 | B29: 45829 | C29: =PROPER(TRIM(Sales_Data!C31)) -> South | D29: =PROPER(TRIM(Sales_Data!D31)) -> Karthik Iyer | E29: =PROPER(TRIM(Sales_Data!E31)) -> Office Chair | F29: =PROPER(TRIM(Sales_Data!F31)) -> Furniture | G29: =IF(Sales_Data!G31=" ",0,Sales_Data!G31) -> 12 | H29: =Sales_Data!H31 -> 6500 | I29: =Table2[[#This Row],[Units]]*Table2[[#This Row],[Unit Price]] -> 78000 | J29: =_xlfn.XLOOKUP(Table2[[#This Row],[Region Clean]],Table4[Region],Table4[Manager]) -> Arjun Reddy
A30: 1106 | B30: 45787 | C30: =PROPER(TRIM(Sales_Data!C175)) -> West | D30: =PROPER(TRIM(Sales_Data!D175)) -> Rohan Shah | E30: =PROPER(TRIM(Sales_Data!E175)) -> Office Chair | F30: =PROPER(TRIM(Sales_Data!F175)) -> Furniture | G30: =IF(Sales_Data!G175=" ",0,Sales_Data!G175) -> 12 | H30: =Sales_Data!H175 -> 6500 | I30: =Table2[[#This Row],[Units]]*Table2[[#This Row],[Unit Price]] -> 78000 | J30: =_xlfn.XLOOKUP(Table2[[#This Row],[Region Clean]],Table4[Region],Table4[Manager]) -> Nikhil Verma
A31: 1102 | B31: 45695 | C31: =PROPER(TRIM(Sales_Data!C127)) -> North | D31: =PROPER(TRIM(Sales_Data!D127)) -> Ravi Kumar | E31: =PROPER(TRIM(Sales_Data!E127)) -> 27In Monitor | F31: =PROPER(TRIM(Sales_Data!F127)) -> Electronics | G31: =IF(Sales_Data!G127=" ",0,Sales_Data!G127) -> 4 | H31: =Sales_Data!H127 -> 18500 | I31: =Table2[[#This Row],[Units]]*Table2[[#This Row],[Unit Price]] -> 74000 | J31: =_xlfn.XLOOKUP(Table2[[#This Row],[Region Clean]],Table4[Region],Table4[Manager]) -> Meera Nair
A32: 1042 | B32: 45779 | C32: =PROPER(TRIM(Sales_Data!C98)) -> South | D32: =PROPER(TRIM(Sales_Data!D98)) -> Karthik Iyer | E32: =PROPER(TRIM(Sales_Data!E98)) -> 27In Monitor | F32: =PROPER(TRIM(Sales_Data!F98)) -> Electronics | G32: =IF(Sales_Data!G98=" ",0,Sales_Data!G98) -> 4 | H32: =Sales_Data!H98 -> 18500 | I32: =Table2[[#This Row],[Units]]*Table2[[#This Row],[Unit Price]] -> 74000 | J32: =_xlfn.XLOOKUP(Table2[[#This Row],[Region Clean]],Table4[Region],Table4[Manager]) -> Arjun Reddy
A33: 1101 | B33: 45836 | C33: =PROPER(TRIM(Sales_Data!C122)) -> West | D33: =PROPER(TRIM(Sales_Data!D122)) -> Rohan Shah | E33: =PROPER(TRIM(Sales_Data!E122)) -> 27In Monitor | F33: =PROPER(TRIM(Sales_Data!F122)) -> Electronics | G33: =IF(Sales_Data!G122=" ",0,Sales_Data!G122) -> 4 | H33: =Sales_Data!H122 -> 18500 | I33: =Table2[[#This Row],[Units]]*Table2[[#This Row],[Unit Price]] -> 74000 | J33: =_xlfn.XLOOKUP(Table2[[#This Row],[Region Clean]],Table4[Region],Table4[Manager]) -> Nikhil Verma
A34: 1023 | B34: 45681 | C34: =PROPER(TRIM(Sales_Data!C2)) -> North | D34: =PROPER(TRIM(Sales_Data!D2)) -> Ravi Kumar | E34: =PROPER(TRIM(Sales_Data!E2)) -> Office Chair | F34: =PROPER(TRIM(Sales_Data!F2)) -> Furniture | G34: =IF(Sales_Data!G2=" ",0,Sales_Data!G2) -> 11 | H34: =Sales_Data!H2 -> 6500 | I34: =Table2[[#This Row],[Units]]*Table2[[#This Row],[Unit Price]] -> 71500 | J34: =_xlfn.XLOOKUP(Table2[[#This Row],[Region Clean]],Table4[Region],Table4[Manager]) -> Meera Nair
A35: 1096 | B35: 45771 | C35: =PROPER(TRIM(Sales_Data!C54)) -> South | D35: =PROPER(TRIM(Sales_Data!D54)) -> Karthik Iyer | E35: =PROPER(TRIM(Sales_Data!E54)) -> Office Chair | F35: =PROPER(TRIM(Sales_Data!F54)) -> Furniture | G35: =IF(Sales_Data!G54=" ",0,Sales_Data!G54) -> 11 | H35: =Sales_Data!H54 -> 6500 | I35: =Table2[[#This Row],[Units]]*Table2[[#This Row],[Unit Price]] -> 71500 | J35: =_xlfn.XLOOKUP(Table2[[#This Row],[Region Clean]],Table4[Region],Table4[Manager]) -> Arjun Reddy
A36: 1054 | B36: 45796 | C36: =PROPER(TRIM(Sales_Data!C125)) -> North | D36: =PROPER(TRIM(Sales_Data!D125)) -> Ananya Rao | E36: =PROPER(TRIM(Sales_Data!E125)) -> Laptop Pro 14 | F36: =PROPER(TRIM(Sales_Data!F125)) -> Electronics | G36: =IF(Sales_Data!G125=" ",0,Sales_Data!G125) -> 1 | H36: =Sales_Data!H125 -> 68000 | I36: =Table2[[#This Row],[Units]]*Table2[[#This Row],[Unit Price]] -> 68000 | J36: =_xlfn.XLOOKUP(Table2[[#This Row],[Region Clean]],Table4[Region],Table4[Manager]) -> Meera Nair
A37: 1153 | B37: 45661 | C37: =PROPER(TRIM(Sales_Data!C22)) -> South | D37: =PROPER(TRIM(Sales_Data!D22)) -> Karthik Iyer | E37: =PROPER(TRIM(Sales_Data!E22)) -> Laptop Pro 14 | F37: =PROPER(TRIM(Sales_Data!F22)) -> Electronics | G37: =IF(Sales_Data!G22=" ",0,Sales_Data!G22) -> 1 | H37: =Sales_Data!H22 -> 68000 | I37: =Table2[[#This Row],[Units]]*Table2[[#This Row],[Unit Price]] -> 68000 | J37: =_xlfn.XLOOKUP(Table2[[#This Row],[Region Clean]],Table4[Region],Table4[Manager]) -> Arjun Reddy
A38: 1158 | B38: 45805 | C38: =PROPER(TRIM(Sales_Data!C9)) -> North | D38: =PROPER(TRIM(Sales_Data!D9)) -> Ravi Kumar | E38: =PROPER(TRIM(Sales_Data!E9)) -> Office Chair | F38: =PROPER(TRIM(Sales_Data!F9)) -> Furniture | G38: =IF(Sales_Data!G9=" ",0,Sales_Data!G9) -> 10 | H38: =Sales_Data!H9 -> 6500 | I38: =Table2[[#This Row],[Units]]*Table2[[#This Row],[Unit Price]] -> 65000 | J38: =_xlfn.XLOOKUP(Table2[[#This Row],[Region Clean]],Table4[Region],Table4[Manager]) -> Meera Nair
A39: 1176 | B39: 45790 | C39: =PROPER(TRIM(Sales_Data!C101)) -> West | D39: =PROPER(TRIM(Sales_Data!D101)) -> Rohan Shah | E39: =PROPER(TRIM(Sales_Data!E101)) -> Office Chair | F39: =PROPER(TRIM(Sales_Data!F101)) -> Furniture | G39: =IF(Sales_Data!G101=" ",0,Sales_Data!G101) -> 10 | H39: =Sales_Data!H101 -> 6500 | I39: =Table2[[#This Row],[Units]]*Table2[[#This Row],[Unit Price]] -> 65000 | J39: =_xlfn.XLOOKUP(Table2[[#This Row],[Region Clean]],Table4[Region],Table4[Manager]) -> Nikhil Verma
A40: 1045 | B40: 45761 | C40: =PROPER(TRIM(Sales_Data!C105)) -> East | D40: =PROPER(TRIM(Sales_Data!D105)) -> Sneha Das | E40: =PROPER(TRIM(Sales_Data!E105)) -> Standing Desk | F40: =PROPER(TRIM(Sales_Data!F105)) -> Furniture | G40: =IF(Sales_Data!G105=" ",0,Sales_Data!G105) -> 4 | H40: =Sales_Data!H105 -> 15500 | I40: =Table2[[#This Row],[Units]]*Table2[[#This Row],[Unit Price]] -> 62000 | J40: =_xlfn.XLOOKUP(Table2[[#This Row],[Region Clean]],Table4[Region],Table4[Manager]) -> Kavita Bose
...

Sheet Pivot Tables
A1: Sales Person | B1: All
A3: Sales | B3: Category | H3: Sales Persons | I3: Sales
A4: Region | B4: Electronics | C4: Furniture | D4: Stationery | E4: Grand Total | H4: Amit Ghosh | I4: 895307
A5: East | B5: 476594 | C5: 899400 | D5: 20870 | E5: 1396864 | H5: Ananya Rao | I5: 952121
A6: North | B6: 2117123 | C6: 547800 | D6: 15350 | E6: 2680273 | H6: Divya Sharma | I6: 651813
A7: South | B7: 1445127 | C7: 581300 | D7: 16450 | E7: 2042877 | H7: Karthik Iyer | I7: 1391064
A8: West | B8: 2257444 | C8: 654500 | D8: 21200 | E8: 2933144 | H8: Priya Mehta | I8: 1512305
A9: Grand Total | B9: 6296288 | C9: 2683000 | D9: 73870 | E9: 9053158 | H9: Ravi Kumar | I9: 1728152
H10: Rohan Shah | I10: 1420839
H11: Sneha Das | I11: 501557
H12: Grand Total | I12: 9053158
A13: Category | B13: Sum of Sales | D13: Row Labels | E13: Sum of Sales
A14: Electronics | B14: 6296288 | D14: East | E14: 1396864
A15: Furniture | B15: 2683000 | D15: North | E15: 2680273
A16: Stationery | B16: 73870 | D16: South | E16: 2042877
A17: Grand Total | B17: 9053158 | D17: West | E17: 2933144
D18: Grand Total | E18: 9053158
A19: Months | B19: Sum of Sales
A20: Jan | B20: 1372298
A21: Feb | B21: 1056357
A22: Mar | B22: 1917415
A23: Apr | B23: 892391
A24: May | B24: 2545980
A25: Jun | B25: 1268717
A26: Grand Total | B26: 9053158

Sheet Lookup
A1: Region | B1: Manager
A2: North | B2: Meera Nair
A3: South | B3: Arjun Reddy
A4: East | B4: Kavita Bose
A5: West | B5: Nikhil Verma
